<?xml version="1.0"?>
<robot name="bookle" xmlns:xacro="http://www.ros.org/wiki/xacro">

	<!-- Constants for robot dimensions -->
	<xacro:property name="PI" value="3.1415926535897931"/>

	<!-- Import all Gazebo-customization elements, including Gazebo colors -->
	<xacro:include filename="$(find bookle_description)/urdf/bookle.gazebo" />

	<link name="base_footprint">
		<collision name="base_footprint_collision">
			<origin xyz="0 0 0"  rpy="0 0 0" />
			<geometry>
				<box size="0.001 0.001 0.001" />
			</geometry>
		</collision>

		<visual name="base_footprint_visual">
			<origin xyz="0 0 0" rpy="0 0 0" />
			<geometry>
				<box size="0.001 0.001 0.001" />
			</geometry>
		</visual>

	</link>

	<link name="base_link">
		<collision name="base_link_collision">
			<origin xyz="0 0 0.1" rpy="0 0 0" />
			<geometry>
				<cylinder radius="0.15" length="0.003" />
			</geometry>
		</collision>

		<visual name="base_link_visual">
			<origin xyz="0 0 0.1" rpy="0 0 0" />
			<geometry>
				<cylinder radius="0.15" length="0.003" />
			</geometry>
		</visual>

		<collision name="front_caster_collision">
			<origin xyz="0.1 0 0.05" rpy="0 1.5707 1.5707" />
			<geometry>
				<cylinder radius="0.05" length="0.015" />
			</geometry>
		</collision>

		<visual name="front_caster_visual">
			<origin xyz="0.1 0 0.05" rpy="0 1.5707 1.5707" />
			<geometry>
				<cylinder radius="0.05" length="0.015" />
			</geometry>
		</visual>

		<collision name="back_caster_collision">
			<origin xyz="-0.1 0 0.05" rpy="0 1.5707 1.5707" />
			<geometry>
				<cylinder radius="0.05" length="0.015" />
			</geometry>
		</collision>

		<visual name="back_caster_visual">
			<origin xyz="-0.1 0 0.05" rpy="0 1.5707 1.5707" />
			<geometry>
				<cylinder radius="0.05" length="0.015" />
			</geometry>
		</visual>

		<inertial>
			<origin xyz="0 0 .1" rpy="0 0 0" />
			<mass value="0.5" />
			<inertia ixx="1.0" ixy="0.0" ixz="0.0" iyy="1.0" iyz="0.0" izz="1.0" />
		</inertial>
	</link>

	<link name="left_wheel">
		<collision name="left_wheel_collision">
			<origin xyz="0 0 0" rpy="0 1.5707 1.5707" />
			<geometry>
				<!-- <cylinder radius="0.04" length="0.015" /> -->
				<box size="0.04 0.04 0.01" />
			</geometry>
		</collision>
		<visual name="left_wheel_visual">
			<origin xyz="0 0 0" rpy="0 1.5707 1.5707" />
			<geometry>
				<!-- <cylinder radius="0.04" length="0.015" /> -->
				<box size="0.04 0.04 0.01" />
			</geometry>
		</visual>

		<inertial>
			<mass value="1" />
			<origin xyz="0 0 0" rpy="0 0 0"/>
			<inertia ixx="1" ixy="0" ixz="0" iyy="1" iyz="0" izz="1" />
		</inertial>
	</link>

	<link name="right_wheel">
		<collision name="right_wheel_collision">
			<origin xyz="0 0 0" rpy="0 1.5707 1.5707" />
			<geometry>
				<!-- <cylinder radius="0.04" length="0.015" /> -->
				<box size="0.04 0.04 0.01" />
			</geometry>
		</collision>
		<visual name="right_wheel_visual">
			<origin xyz="0 0 0" rpy="0 1.5707 1.5707" />
			<geometry>
				<!-- <cylinder radius="0.04" length="0.015" /> -->
				<box size="0.04 0.04 0.01" />
			</geometry>
		</visual>

		<inertial>
			<mass value="1" />
			<origin xyz="0 0 0" rpy="0 0 0"/>
			<inertia ixx="1" ixy="0" ixz="0" iyy="1" iyz="0" izz="1" />
		</inertial>
	</link>

	<link name="left_frame">
		<collision name="left_frame1_collision">
			<origin xyz="0 0.0075 0" rpy="0 0 0" />
			<geometry>
				<box size=".08 .002 .06" />
			</geometry>
		</collision>
		<visual name="left_frame1_visual">
			<origin xyz="0 0.0075 0" rpy="0 0 0" />
			<geometry>
				<box size=".08 .002 .06" />
			</geometry>
		</visual>

		<collision name="left_frame2_collision">
			<origin xya="0 -0.0075 0" rpy="0 0 0"/>
			<geometry>
				<box size=".08 .002 .06" />
			</geometry>
		</collision>
		<visual name="left_frame2_visual">
			<origin xyz="0 -0.0075 0" rpy="0 0 0" />
			<geometry>
				<box size=".08 .002 .06" />
			</geometry>
		</visual>

		<inertial>
			<origin xyz="0 0 0" rpy="0 0 0" />
			<mass value="1" />
			<inertia ixx="1.0" ixy="0.0" ixz="0.0" iyy="1.0" iyz="0.0" izz="1.0" />
		</inertial>
	</link>

	<link name="right_frame">
		<collision name="right_frame1_collision">
			<origin xyz="0 .0075 0" rpy="0 0 0" />
			<geometry>
				<box size=".08 .002 .06" />
			</geometry>
		</collision>
		<visual name="right_frame1_visual">
			<origin xyz="0 .0075 0" rpy="0 0 0" />
			<geometry>
				<box size=".08 .002 .06" />
			</geometry>
		</visual>

		<collision name="right_frame2_collision">
			<origin xyz="0 -0.0075 0" rpy="0 0 0" />
			<geometry>
				<box size=".08 .002 .06" />
			</geometry>
		</collision>
		<visual name="right_frame2_visual">
			<origin xyz="0 -0.0075 0" rpy="0 0 0" />
			<geometry>
				<box size=".08 .002 .06" />
			</geometry>
		</visual>

		<inertial>
			<origin xyz="0 0 0" rpy="0 0 0" />
			<mass value="1" />
			<inertia ixx="1.0" ixy="0.0" ixz="0.0" iyy="1.0" iyz="0.0" izz="1.0" />
		</inertial>
	</link>

	<joint type="fixed" name="base_footprint_joint">
		<origin xyz="0 0 0" rpy="0 0 0" />
		<child link="base_link" />
		<parent link="base_footprint" />
	</joint>

	<joint type="continuous" name="left_wheel_joint">
		<origin xyz="0 0 -0.03" rpy="0 0 0" />
		<child link="left_wheel" />
		<parent link="left_frame" />
		<axis xyz="0 1 0" />
		<dynamics damping="0.1" friction="0.1"/>
		<limit effort="100" velocity="100"/>
		<!-- <limit effort="30" velocity="0.5" lower="-3.14" upper="3.14"/>  -->
	</joint>

	<joint type="continuous" name="right_wheel_joint">
		<origin xyz="0 0 -0.03" rpy="0 0 0" />
		<child link="right_wheel" />
		<parent link="right_frame" />
		<axis xyz="0 1 0" />
		<dynamics damping="0.1" friction="0.2"/>
		<limit effort="100" velocity="100"/>
		<!-- <limit effort="30" velocity="0.5" lower="-3.14" upper="3.14"/>  -->
	</joint>

	<joint type="fixed" name="left_frame_joint">
		<origin xyz="0 0.1 0.07" rpy="0 0 0" />
		<child link="left_frame" />
		<parent link="base_link" />
		<axis xyz="1 0 0" />
		<dynamics damping="0.1" friction="0.2"/>
	</joint>

	<joint type="fixed" name="right_frame_joint">
		<origin xyz="0 -0.1 0.07" rpy="0 0 0" />
		<child link="right_frame" />
		<parent link="base_link" />
		<axis xyz="1 0 0" />
		<dynamics damping="0.1" friction="0.1"/>
	</joint>

	<transmission name="left_wheel_trans" type="SimpleTransmission">
		<type>transmission_interface/SimpleTransmission</type>
		<actuator name="left_wheel_motor">
			<mechanicalReduction>1</mechanicalReduction>
		</actuator>
		<joint name="left_wheel_joint">
			<hardwareInterface>VelocityJointInterface</hardwareInterface>
		</joint>
	</transmission>

	<transmission name="right_wheel_trans" type="SimpleTransmission">
		<type>transmission_interface/SimpleTransmission</type>
		<actuator name="right_wheel_motor">
			<mechanicalReduction>1</mechanicalReduction>
		</actuator>
		<joint name="right_wheel_joint">
			<hardwareInterface>VelocityJointInterface</hardwareInterface>
		</joint>
	</transmission>


	<!-- <include>
		<uri>model://hokuyo</uri>
		<pose>0.1 0 0.135 0 0 0</pose>
	</include>
	<joint name="hokuyo_joint" type="revolute">
		<child>hokuyo::link</child>
		<parent>base_link</parent>
		<axis>
			<xyz>0 0 1</xyz>
			<limit>
				<upper>0</upper>
				<lower>0</lower>
			</limit>
		</axis>
	</joint> -->

	<joint name="hokuyo_joint" type="fixed">
		<axis xyz="0 0 1" />
		<origin xyz="0.1 0 0.135" rpy="0 0 0"/>
		<parent link="base_link"/>
		<child link="base_laser"/>
	</joint>

	<!-- Hokuyo Laser -->
	<link name="base_laser">
		<collision>
			<origin xyz="0 0 0" rpy="0 0 0"/>
			<geometry>
				<box size="0.1 0.1 0.1"/>
			</geometry>
		</collision>

		<visual>
			<origin xyz="0 0 0" rpy="0 0 0"/>
			<geometry>
				<mesh filename="package://bookle_description/meshes/hokuyo.dae"/>
			</geometry>
		</visual>

		<inertial>
			<mass value="1e-5" />
			<origin xyz="0 0 0" rpy="0 0 0"/>
			<inertia ixx="1e-6" ixy="0" ixz="0" iyy="1e-6" iyz="0" izz="1e-6" />
		</inertial>
	</link>

</robot>
